Workbook
Name Accrued_Income: AI!$B$3
Name Amex_Loan: AL!$B$5
Name B_S: BS!$B$4
Name ColumnTitle1: #REF!
Name EndingBalance: -FV(InterestRate/12,AP!PaymentNumber,-AP!MonthlyPayment,LoanAmount)
Name EndingBalance: -FV(InterestRate/12,PaymentNumber,-MonthlyPayment,LoanAmount)
Name HeaderRow: ROW(#REF!)
Name I_L: IL!$B$5
Name InterestAmt: -IPMT(InterestRate/12,AP!PaymentNumber,NumberOfPayments,LoanAmount)
Name InterestAmt: -IPMT(InterestRate/12,PaymentNumber,NumberOfPayments,LoanAmount)
Name InterestRate: #REF!
Name LastCol: COUNTA(#REF!)
Name LastRow: MATCH(9.99E+307,#REF!)
Name LoanAmount: #REF!
Name LoanIsGood: IF(LoanAmount*InterestRate*LoanYears*LoanStartDate>0,1,0)
Name LoanIsGood: IF(LoanAmount*InterestRate*LoanYears*LoanStartDate>0,1,0)
Name LoanIsNotPaid: IF(AP!PaymentNumber<=NumberOfPayments,1,0)
Name LoanIsNotPaid: IF(PaymentNumber<=NumberOfPayments,1,0)
Name LoanStartDate: #REF!
Name LoanValue: -FV(InterestRate/12,AP!PaymentNumber-1,-AP!MonthlyPayment,LoanAmount)
Name LoanValue: -FV(InterestRate/12,PaymentNumber-1,-MonthlyPayment,LoanAmount)
Name LoanYears: #REF!
Name MonthlyPayment: -PMT(InterestRate/12,NumberOfPayments,LoanAmount)
Name MonthlyPayment: -PMT(InterestRate/12,NumberOfPayments,LoanAmount)
Name NumberOfPayments: #REF!
Name P_L: 'Profit and Loss by Month'!$B$3
Name PaymentDate: DATE(YEAR(LoanStartDate),MONTH(LoanStartDate)+AP!PaymentNumber,DAY(LoanStartDate))
Name PaymentDate: DATE(YEAR(LoanStartDate),MONTH(LoanStartDate)+PaymentNumber,DAY(LoanStartDate))
Name PaymentNumber: ROW()-HeaderRow
Name PaymentNumber: ROW()-HeaderRow
Name PL_DM: 'Profit & Loss - Division(Month)'!$B$3
Name PL_YTD: 'Profit and Loss - Division(YTD)'!$B$3
Name Principal: -PPMT(InterestRate/12,AP!PaymentNumber,NumberOfPayments,LoanAmount)
Name Principal: -PPMT(InterestRate/12,PaymentNumber,NumberOfPayments,LoanAmount)
Name PrintArea_SET: OFFSET(#REF!,,,LastRow,LastCol)
Name PrintArea_SET: OFFSET(#REF!,,,LastRow,LastCol)
Name R_L: RL!$B$5
Name RowTitleRegion1..D6: #REF!
Name RowTitleRegion2..H6: #REF!
Name Total_Interest: #REF!
Name TotalLoanCost: #REF!

Sheet Project Profitability Points
A1: 1. Improving Project Profitability Reporting
A2: Right now, we have observed that project profitability is not aligning because employees are not entering their full working hours in the toggle.
A4: Here’s what’s happening:
A5: Employees record their time against projects in Toggle.
A6: Payroll is processed separately, and we record total payroll cost directly in P&L.
A7: When working on project profitability, we divide the employee’s payroll cost based on the hours they entered in Toggle.
A9: But here’s the problem:
A10: If an employee works 60 hours in two weeks, and records only 4 hours in Toggle, then all of their pay is being assigned to just those 4 hours for two projects.
A11: This makes the project cost look very high, and the profitability report becomes inaccurate.
A28: Suggested Solution:
A29: Set a Minimum Time Entry Benchmark:
A30: Every employee should enter their full working hours (for example, 8 hours per day or 40 hours per week).
... A37: If they record only 4 hours → cost per hour = $500 → makes the project, look much more expensive than it really is.

Sheet Cover
A3: Pacific Nexus
A5: Financial Workpapers for the
A6: Period Ending 03/31/2026
A9: Prepared by:
A17: Analytix Solutions
A19: For Internal Management Purpose Only

Sheet Index
A1: =Cover!A3 -> Pacific Nexus
A2: =Cover!A6 -> Period Ending 03/31/2026
A4: Financial Statements Index
A6: Sr. No. | B6: Particulars | C6: Reference
A9: 1 | B9: Balance sheet | C9: BS
A11: =+A9+1 -> 2 | B11: Profit and Loss Account-Monthly/Quarterly | C11: PL
A13: =+A11+1 -> 3 | B13: Profit and Loss Account- Division (YTD) | C13: PL-Division (YTD)
A15: 4 | B15: Profit & Loss - Division(Month) | C15: PL-Division (Month)
A17: 5 | B17: Statement of Cash Flow | C17: Cash Flow
A19: 6 | B19: Profit and Loss - YOY Summary | C19: P&L YOY Summary
A21: 7 | B21: Profit and Loss - YOY Detail | C21: P&L YOY Detail
A23: 8 | B23: Project Profitability Report | C23: PPR

Sheet BS
B2: =Index!A1 -> Pacific Nexus | F2: Home
B3: =Index!A2 -> Period Ending 03/31/2026 | F3: Profit & Loss
B4: Balance Sheet | F4: PL-Division (Month)
F5: PL-Division (YTD)
F6: Cash Flow
B7: Particulars | C7: Amount | D7: Schedule | E7: Comments
B8: Assets
B9: Current Assets
B10: Bank Accounts
B11: 1000 CNB Checking #2640 | C11: 93993.55 | E11: Bank is reconciled as of 03/31/2026
B12: Total for Bank Accounts | C12: =C10+C11 -> 93993.55
B13: Accounts Receivable
B14: 1100 Accounts Receivable | C14: 169897.05 | D14: AR | E14: Kindly walk through attached Accounts Receivable aging report for your review and feedback, if any.
B15: Total for Accounts Receivable | C15: =C13+C14 -> 169897.05
B16: Other Current Assets
B17: 1300 Prepaid Expenses | C17: 18571.31 | D17: PE
B18: 1380 Accrued Income | C18: 119875.41 | D18: Accrual Income
B19: Total for Other Current Assets | C19: =C16+C17+C18 -> 138446.72
B20: Total for Current Assets | C20: =C9+C12+C15+C19 -> 402337.32
B21: Fixed Assets
B22: 1425 Computer & Office Equipment | C22: 226991.82 | D22: FA | E22: There was an addition of $8,725.00 in March ’26 related to alarm installation.
B23: 1430 Accumulated Depreciation - Computer & Office Equipment | C23: -91592.16
B24: Total for 1425 Computer & Office Equipment | C24: =C22+C23 -> 135399.66
B25: 1435 Leasehold Improvements | C25: 12840
B26: 1440 Accumulated Depreciation - Leasehold Improvements | C26: -3754.44
B27: Total for 1435 Leasehold Improvements | C27: =C25+C26 -> 9085.56
B28: Total for Fixed Assets | C28: =C21+C24+C27 -> 144485.22
B29: Other Assets
B30: 1505 Goodwill | C30: 2236541.8 | D30: OA
B31: 1510 Accumulated Amortization - Goodwill | C31: -298205.45
B32: Total for 1505 Goodwill | C32: =C30+C31 -> 1938336.3
B33: 1515 Loan Closing Costs | C33: 67628.25
B34: 1520 Accumulated Amortization - Loan Closing Costs | C34: -13525.55
B35: Total for 1515 Loan Closing Costs | C35: =C33+C34 -> 54102.7
B36: 1540 Purchase Cost - NS Printing | C36: 111368.67
B37: 1545 Accumulated Amortization - Purchase Cost - NS Printing | C37: -8739.04
B38: Total for 1540 Purchase Cost - NS Printing | C38: =C36+C37 -> 102629.63
B39: 1600 Security Deposit | C39: 94343.18
B40: Total for Other Assets | C40: =C29+C32+C35+C38+C39 -> 2189411.8
B41: Total for Assets | C41: =C20+C28+C40 -> 2736234.4
...

Sheet Charts

Sheet Charts Data
B2: Particulars | C2: 01/2025 | D2: 02/2025 | E2: 03/2025 | F2: 04/2025 | G2: 05/2025 | H2: 06/2025 | I2: 07/2025 | J2: 08/2025 | K2: 09/2025 | L2: YTD
B3: Sales % of change | C3: 0 | D3: =(D4-C4)/C4 -> -0.14481786 | E3: =(E4-D4)/D4 -> -0.24802246 | F3: =(F4-E4)/E4 -> 1.5233796 | G3: =(G4-F4)/F4 -> -0.52972321 | H3: =(H4-G4)/G4 -> 0.81196107 | I3: =(I4-H4)/H4 -> -0.18211049 | J3: =(J4-I4)/I4 -> -0.12695659 | K3: =(K4-J4)/J4 -> 0.30026693
B4: Total Sales | C4: 206276.98 | D4: 176404.39 | E4: 132652.14 | F4: 334731.7 | G4: 157416.55 | H4: 285232.66 | I4: 233288.8 | J4: 203671.25 | K4: 264826.99 | L4: =SUM(C4:K4) -> 1994501.5
B5: Photography % of change | C5: 0 | D5: =(D6-C6)/C6 -> 1.3895737 | E5: =(E6-D6)/D6 -> -0.5536826 | F5: =(F6-E6)/E6 -> 4.3410189 | G5: =(G6-F6)/F6 -> -0.81539028 | H5: =(H6-G6)/G6 -> 1.696871 | I5: =(I6-H6)/H6 -> -0.36305488 | J5: =(J6-I6)/I6 -> -0.18644345 | K5: =(K6-J6)/J6 -> 0.082095012
B6: PN Photography | C6: 39995 | D6: 95571 | E6: 42655 | F6: 227821.16 | G6: 42058 | H6: 113425 | I6: 72245.5 | J6: 58775.8 | K6: 63601 | L6: =SUM(C6:K6) -> 756147.46
B7: Printing % of change | C7: 0 | D7: =(D8-C8)/C8 -> -0.33378721 | E7: =(E8-D8)/D8 -> 0.073260166 | F7: =(F8-E8)/E8 -> 0.59360802 | G7: =(G8-F8)/F8 -> 0.14193989 | H7: =(H8-G8)/G8 -> 0.53100262 | I7: =(I8-H8)/H8 -> -0.068474013 | J7: =(J8-I8)/I8 -> -0.094648448 | K7: =(K8-J8)/J8 -> 0.3887668
B8: PN Printing | C8: 86243 | D8: 57456.19 | E8: 61665.44 | F8: 98270.54 | G8: 112219.05 | H8: 171807.66 | I8: 160043.3 | J8: 144895.45 | K8: 201225.99 | L8: =SUM(C8:K8) -> 1093826.6
B9: Gross Profit | C9: 93355.12 | D9: 85500.19 | E9: -10454.59 | F9: 218949.23 | G9: 11938.71 | H9: 202139.42 | I9: 86590.35 | J9: 109796.02 | K9: 171932.47 | L9: =SUM(C9:K9) -> 969746.92
B10: GP % | C10: =C9/C4 -> 0.45257168 | D10: =D9/D4 -> 0.48468289 | E10: =E9/E4 -> -0.078812072 | F10: =F9/F4 -> 0.65410366 | G10: =G9/G4 -> 0.075841517 | H10: =H9/H4 -> 0.70868259 | I10: =I9/I4 -> 0.37117234 | J10: =J9/J4 -> 0.53908453 | ... L10: =L9/L4 -> 0.48621018
B11: EBITDA | C11: -59483.9 | D11: -56308.1 | E11: -131287.97 | F11: 52520.36 | G11: -80565.19 | H11: 103493.86 | I11: -32039.53 | J11: 16603.65 | K11: 92337.52 | L11: =SUM(C11:K11) -> -94729.3
B12: EBITDA % | C12: =C11/C4 -> -0.28836907 | D12: =D11/D4 -> -0.31919897 | E12: =E11/E4 -> -0.98971619 | F12: =F11/F4 -> 0.15690286 | G12: =G11/G4 -> -0.51179619 | H12: =H11/H4 -> 0.36284015 | I12: =I11/I4 -> -0.13733848 | J12: =J11/J4 -> 0.081521815 | ... L12: =L11/L4 -> -0.047495227
B13: EBIT | C13: -73180.12 | D13: -70004.32 | E13: -145113.19 | F13: 38522.02 | G13: -94563.53 | H13: 89495.52 | I13: -46037.87 | J13: 2605.31 | K13: 78339.18 | L13: =SUM(C13:K13) -> -219937
B14: EBIT % | C14: =C13/C4 -> -0.3547663 | D14: =D13/D4 -> -0.39684001 | E14: =E13/E4 -> -1.0939378 | F14: =F13/F4 -> 0.11508327 | G14: =G13/G4 -> -0.60072165 | H14: =H13/H4 -> 0.31376323 | I14: =I13/I4 -> -0.19734282 | J14: =J13/J4 -> 0.012791742 | ... L14: =L13/L4 -> -0.11027167
B15: PBT/PAT | C15: -97938.46 | D15: -94067.95 | E15: -169679 | F15: 13224.57 | G15: -120325.33 | H15: 64682.21 | I15: -73099.63 | J15: -24017.16 | K15: 52551.81 | L15: =SUM(C15:K15) -> -448668.94
B16: PBT/PAT % | C16: =C15/C4 -> -0.47479103 | D16: =D15/D4 -> -0.53325175 | E16: =E15/E4 -> -1.2791275 | F16: =F15/F4 -> 0.03950797 | G16: =G15/G4 -> -0.76437535 | H16: =H15/H4 -> 0.22677 | I16: =I15/I4 -> -0.31334393 | J16: =J15/J4 -> -0.11792121 | ... L16: =L15/L4 -> -0.22495293
B63: COGS | C63: YTD | D63: %
B64: Cost of Materials | C64: 318180.89 | D64: =C64/$C$67 -> 0.15952903
B65: Travels and Meals | C65: 10319.72 | D65: =C65/$C$67 -> 0.005174085
B66: Wages & Taxes | C66: 696253.93 | D66: =C66/$C$67 -> 0.3490867
B67: Total Sales | C67: 1994501.5 | D67: =C67/$C$67 -> 1
B92: Operating Expenses | C92: YTD | D92: % of Sales | E92: % of Op. Ex
B93: Salaries and Taxes | C93: ='Profit and Loss by Month'!O25 -> 0 | D93: =C93/$C$99 -> 0 | E93: =C93/$C$100 -> #REF!
B94: Shareholder's Compensation | C94: ='Profit and Loss by Month'!O41 -> 1175 | D94: =C94/$C$99 -> 0.0016447405 | E94: =C94/$C$100 -> #REF!
B95: Professional Fees | C95: ='Profit and Loss by Month'!O35 -> 12549.99 | D95: =C95/$C$99 -> 0.017567214 | E95: =C95/$C$100 -> #REF!
B96: Office Expesnes | C96: ='Profit and Loss by Month'!O47 -> 7736.87 | D96: =C96/$C$99 -> 0.010829909 | E96: =C96/$C$100 -> #REF!
B97: Facility Expenses | C97: ='Profit and Loss by Month'!O54 -> 8503.67 | D97: =C97/$C$99 -> 0.01190326 | E97: =C97/$C$100 -> #REF!
B98: Other Operating Expenses | C98: ='Profit and Loss by Month'!O74+13098.54 -> 72647.45 | D98: =C98/$C$99 -> 0.10169038 | E98: =C98/$C$100 -> #REF!
B99: Total Sales | C99: ='Profit and Loss by Month'!O11 -> 714398.42 | D99: =C99/$C$99 -> 1
B100: Total Operating Expenses | C100: ='Profit and Loss by Month'!O75-'Profit and Loss by Month'!#REF! -> #REF!

Sheet Profit and Loss by Month
B2: =Index!A1 -> Pacific Nexus | V2: Home
B3: Profit and Loss | V3: Balance Sheet
B4: =Index!A2 -> Period Ending 03/31/2026 | V4: PL-Division (Month)
V5: PL-Division (YTD)
C6: 46023 | G6: 46054 | K6: 46082 | O6: YTD | S6: Remarks | T6: Actual % on Sales | U6: Projected % on Sales
C7: Actual | D7: Budget | E7: Variance | F7: % of Budget | G7: Actual | H7: Budget | I7: Variance | J7: % of Budget | K7: Actual | L7: Budget | M7: Variance | N7: % of Budget | O7: Actual | P7: Budget | Q7: Variance | R7: % of Budget
B8: Income
B9: 4005 Sales Revenue | C9: =206737.15 -> 206737.15 | D9: =345833.33 -> 345833.33 | E9: =(C9)-(D9) -> -139096.18 | F9: =IF(D9=0,"",(C9)/(D9)) -> 0.59779417 | G9: =221461.62 -> 221461.62 | H9: =345833.33 -> 345833.33 | I9: =(G9)-(H9) -> -124371.71 | J9: =IF(H9=0,"",(G9)/(H9)) -> 0.64037096 | K9: =289563.38 -> 289563.38 | L9: =345833.33 -> 345833.33 | M9: =(K9)-(L9) -> -56269.95 | N9: =IF(L9=0,"",(K9)/(L9)) -> 0.83729171 | O9: =((C9)+(G9))+(K9) -> 717762.15 | P9: =((D9)+(H9))+(L9) -> 1037500 | Q9: =(O9)-(P9) -> -319737.84 | R9: =IF(P9=0,"",(O9)/(P9)) -> 0.69181895
B10: 4010 Sales Discount | C10: =-1952.59 -> -1952.59 | E10: =(C10)-(D10) -> -1952.59 | F10: =IF(D10=0,"",(C10)/(D10)) | G10: =-515.62 -> -515.62 | I10: =(G10)-(H10) -> -515.62 | J10: =IF(H10=0,"",(G10)/(H10)) | K10: =-895.52 -> -895.52 | M10: =(K10)-(L10) -> -895.52 | N10: =IF(L10=0,"",(K10)/(L10)) | O10: =((C10)+(G10))+(K10) -> -3363.73 | P10: =((D10)+(H10))+(L10) -> 0 | Q10: =(O10)-(P10) -> -3363.73 | R10: =IF(P10=0,"",(O10)/(P10))
B11: Total Income | C11: =(C9)+(C10) -> 204784.56 | D11: =(D9)+(D10) -> 345833.33 | E11: =(C11)-(D11) -> -141048.77 | F11: =IF(D11=0,"",(C11)/(D11)) -> 0.59214813 | G11: =(G9)+(G10) -> 220946 | H11: =(H9)+(H10) -> 345833.33 | I11: =(G11)-(H11) -> -124887.33 | J11: =IF(H11=0,"",(G11)/(H11)) -> 0.63888001 | K11: =(K9)+(K10) -> 288667.86 | L11: =(L9)+(L10) -> 345833.33 | M11: =(K11)-(L11) -> -57165.47 | N11: =IF(L11=0,"",(K11)/(L11)) -> 0.83470225 | O11: =((C11)+(G11))+(K11) -> 714398.42 | P11: =((D11)+(H11))+(L11) -> 1037500 | Q11: =(O11)-(P11) -> -323101.57 | R11: =IF(P11=0,"",(O11)/(P11)) -> 0.6885768 | S11: We achieved approximately 83% of the budgeted sales for Mar ’26. Compared to Jan ’26 and Feb ’26, this reflects an improvement and indicates that we are moving closer to the budgeted sales levels.
B12: Cost of Goods Sold
B13: 5005 Cost of Materials | C13: =29209.55 -> 29209.55 | D13: =44958.33 -> 44958.33 | E13: =(C13)-(D13) -> -15748.78 | F13: =IF(D13=0,"",(C13)/(D13)) -> 0.64970274 | G13: =23283.51 -> 23283.51 | H13: =44958.33 -> 44958.33 | I13: =(G13)-(H13) -> -21674.82 | J13: =IF(H13=0,"",(G13)/(H13)) -> 0.5178909 | K13: =34847.91 -> 34847.91 | L13: =44958.33 -> 44958.33 | M13: =(K13)-(L13) -> -10110.42 | N13: =IF(L13=0,"",(K13)/(L13)) -> 0.77511576 | O13: =((C13)+(G13))+(K13) -> 87340.97 | P13: =((D13)+(H13))+(L13) -> 134874.99 | Q13: =(O13)-(P13) -> -47534.02 | R13: =IF(P13=0,"",(O13)/(P13)) -> 0.6475698
B14: 5015 Travels and Meals | E14: =(C14)-(D14) -> 0 | F14: =IF(D14=0,"",(C14)/(D14)) | I14: =(G14)-(H14) -> 0 | J14: =IF(H14=0,"",(G14)/(H14)) | K14: 0 | M14: =(K14)-(L14) -> 0 | N14: =IF(L14=0,"",(K14)/(L14)) | O14: =((C14)+(G14))+(K14) -> 0 | P14: =((D14)+(H14))+(L14) -> 0 | Q14: =(O14)-(P14) -> 0 | R14: =IF(P14=0,"",(O14)/(P14))
B15: 5065 Wages | C15: =90285.21 -> 90285.21 | D15: =76465.59 -> 76465.59 | E15: =(C15)-(D15) -> 13819.62 | F15: =IF(D15=0,"",(C15)/(D15)) -> 1.1807299 | G15: =86016.39 -> 86016.39 | H15: =76465.59 -> 76465.59 | I15: =(G15)-(H15) -> 9550.8 | J15: =IF(H15=0,"",(G15)/(H15)) -> 1.1249032 | K15: =97713.83 -> 97713.83 | L15: =76465.59 -> 76465.59 | M15: =(K15)-(L15) -> 21248.24 | N15: =IF(L15=0,"",(K15)/(L15)) -> 1.2778798 | O15: =((C15)+(G15))+(K15) -> 274015.43 | P15: =((D15)+(H15))+(L15) -> 229396.77 | Q15: =(O15)-(P15) -> 44618.66 | R15: =IF(P15=0,"",(O15)/(P15)) -> 1.1945043
B16: 5070 Payroll Tax Expense | C16: =9791.27 -> 9791.27 | D16: =6117.25 -> 6117.25 | E16: =(C16)-(D16) -> 3674.02 | F16: =IF(D16=0,"",(C16)/(D16)) -> 1.6005999 | G16: =7407.13 -> 7407.13 | H16: =6117.25 -> 6117.25 | I16: =(G16)-(H16) -> 1289.88 | J16: =IF(H16=0,"",(G16)/(H16)) -> 1.2108595 | K16: =8070.23 -> 8070.23 | L16: =6117.25 -> 6117.25 | M16: =(K16)-(L16) -> 1952.98 | N16: =IF(L16=0,"",(K16)/(L16)) -> 1.3192578 | O16: =((C16)+(G16))+(K16) -> 25268.63 | P16: =((D16)+(H16))+(L16) -> 18351.75 | Q16: =(O16)-(P16) -> 6916.88 | R16: =IF(P16=0,"",(O16)/(P16)) -> 1.3769057
B17: 5075 Employee Benefits | C17: =3351.49 -> 3351.49 | D17: =3058.62 -> 3058.62 | E17: =(C17)-(D17) -> 292.87 | F17: =IF(D17=0,"",(C17)/(D17)) -> 1.0957523 | G17: =3877.27 -> 3877.27 | H17: =3058.62 -> 3058.62 | I17: =(G17)-(H17) -> 818.65 | J17: =IF(H17=0,"",(G17)/(H17)) -> 1.2676534 | K17: =4829.13 -> 4829.13 | L17: =3058.62 -> 3058.62 | M17: =(K17)-(L17) -> 1770.51 | N17: =IF(L17=0,"",(K17)/(L17)) -> 1.5788591 | O17: =((C17)+(G17))+(K17) -> 12057.89 | P17: =((D17)+(H17))+(L17) -> 9175.86 | Q17: =(O17)-(P17) -> 2882.03 | R17: =IF(P17=0,"",(O17)/(P17)) -> 1.3140883
B18: Total Cost of Goods Sold | C18: =((((C13)+(C14))+(C15))+(C16))+(C17) -> 132637.52 | D18: =((((D13)+(D14))+(D15))+(D16))+(D17) -> 130599.79 | E18: =(C18)-(D18) -> 2037.73 | F18: =IF(D18=0,"",(C18)/(D18)) -> 1.0156029 | G18: =((((G13)+(G14))+(G15))+(G16))+(G17) -> 120584.3 | H18: =((((H13)+(H14))+(H15))+(H16))+(H17) -> 130599.79 | I18: =(G18)-(H18) -> -10015.49 | J18: =IF(H18=0,"",(G18)/(H18)) -> 0.92331159 | K18: =((((K13)+(K14))+(K15))+(K16))+(K17) -> 145461.1 | L18: =((((L13)+(L14))+(L15))+(L16))+(L17) -> 130599.79 | M18: =(K18)-(L18) -> 14861.31 | N18: =IF(L18=0,"",(K18)/(L18)) -> 1.1137928 | O18: =((C18)+(G18))+(K18) -> 398682.92 | P18: =((D18)+(H18))+(L18) -> 391799.37 | Q18: =(O18)-(P18) -> 6883.55 | R18: =IF(P18=0,"",(O18)/(P18)) -> 1.0175691 | T18: =K18/$K$11 -> 0.50390473 | U18: =L18/$L$11 -> 0.37763795
B19: Gross Profit | C19: =(C11)-(C18) -> 72147.04 | D19: =(D11)-(D18) -> 215233.54 | E19: =(C19)-(D19) -> -143086.5 | F19: =IF(D19=0,"",(C19)/(D19)) -> 0.33520352 | G19: =(G11)-(G18) -> 100361.7 | H19: =(H11)-(H18) -> 215233.54 | I19: =(G19)-(H19) -> -114871.84 | J19: =IF(H19=0,"",(G19)/(H19)) -> 0.4662921 | K19: =(K11)-(K18) -> 143206.76 | L19: =(L11)-(L18) -> 215233.54 | M19: =(K19)-(L19) -> -72026.78 | N19: =IF(L19=0,"",(K19)/(L19)) -> 0.66535522 | O19: =((C19)+(G19))+(K19) -> 315715.5 | P19: =((D19)+(H19))+(L19) -> 645700.62 | Q19: =(O19)-(P19) -> -329985.12 | R19: =IF(P19=0,"",(O19)/(P19)) -> 0.48895028 | S19: We achieved approximately 65% of the targeted gross profit, which is an improvement compared to Jan ’26 and Feb ’26, primarily driven by a 10% increase in sales. The shortfall is largely volume‑driven, and margins are expected to improve as sales continue to pick up. | T19: =K19/$K$11 -> 0.49609527 | U19: =L19/$L$11 -> 0.62236205
B20: Expenses
B21: 6100 Payroll Expenses | E21: =(C21)-(D21) -> 0 | F21: =IF(D21=0,"",(C21)/(D21)) | I21: =(G21)-(H21) -> 0 | J21: =IF(H21=0,"",(G21)/(H21)) | M21: =(K21)-(L21) -> 0 | N21: =IF(L21=0,"",(K21)/(L21)) | O21: =((C21)+(G21))+(K21) -> 0 | P21: =((D21)+(H21))+(L21) -> 0 | Q21: =(O21)-(P21) -> 0 | R21: =IF(P21=0,"",(O21)/(P21))
B22: 6105 Salaries & Wages | C22: =23690.14 -> 23690.14 | D22: =21626.45 -> 21626.45 | E22: =(C22)-(D22) -> 2063.69 | F22: =IF(D22=0,"",(C22)/(D22)) -> 1.0954244 | G22: =19384.61 -> 19384.61 | H22: =21626.45 -> 21626.45 | I22: =(G22)-(H22) -> -2241.84 | J22: =IF(H22=0,"",(G22)/(H22)) -> 0.89633805 | K22: =21461.53 -> 21461.53 | L22: =21626.45 -> 21626.45 | M22: =(K22)-(L22) -> -164.92 | N22: =IF(L22=0,"",(K22)/(L22)) -> 0.99237415 | O22: =((C22)+(G22))+(K22) -> 64536.28 | P22: =((D22)+(H22))+(L22) -> 64879.35 | Q22: =(O22)-(P22) -> -343.07 | R22: =IF(P22=0,"",(O22)/(P22)) -> 0.99471219
B23: 6115 Payroll Tax Expense | C23: =1899.81 -> 1899.81 | D23: =1730.12 -> 1730.12 | E23: =(C23)-(D23) -> 169.69 | F23: =IF(D23=0,"",(C23)/(D23)) -> 1.0980799 | G23: =1358.66 -> 1358.66 | H23: =1730.12 -> 1730.12 | I23: =(G23)-(H23) -> -371.46 | J23: =IF(H23=0,"",(G23)/(H23)) -> 0.78529813 | K23: =3998.69 -> 3998.69 | L23: =1730.12 -> 1730.12 | M23: =(K23)-(L23) -> 2268.57 | N23: =IF(L23=0,"",(K23)/(L23)) -> 2.3112212 | O23: =((C23)+(G23))+(K23) -> 7257.16 | P23: =((D23)+(H23))+(L23) -> 5190.36 | Q23: =(O23)-(P23) -> 2066.8 | R23: =IF(P23=0,"",(O23)/(P23)) -> 1.3981997
B24: 6120 Employee Benefits | C24: =525.64 -> 525.64 | D24: =865.06 -> 865.06 | E24: =(C24)-(D24) -> -339.42 | F24: =IF(D24=0,"",(C24)/(D24)) -> 0.60763415 | G24: =781.15 -> 781.15 | H24: =865.06 -> 865.06 | I24: =(G24)-(H24) -> -83.91 | J24: =IF(H24=0,"",(G24)/(H24)) -> 0.90300095 | K24: =1159.91 -> 1159.91 | L24: =865.06 -> 865.06 | M24: =(K24)-(L24) -> 294.85 | N24: =IF(L24=0,"",(K24)/(L24)) -> 1.3408434 | O24: =((C24)+(G24))+(K24) -> 2466.7 | P24: =((D24)+(H24))+(L24) -> 2595.18 | Q24: =(O24)-(P24) -> -128.48 | R24: =IF(P24=0,"",(O24)/(P24)) -> 0.95049284
B25: 6125 Employee Bonus | D25: =821.81 -> 821.81 | E25: =(C25)-(D25) -> -821.81 | F25: =IF(D25=0,"",(C25)/(D25)) -> 0 | H25: =821.81 -> 821.81 | I25: =(G25)-(H25) -> -821.81 | J25: =IF(H25=0,"",(G25)/(H25)) -> 0 | L25: =821.81 -> 821.81 | M25: =(K25)-(L25) -> -821.81 | N25: =IF(L25=0,"",(K25)/(L25)) -> 0 | O25: =((C25)+(G25))+(K25) -> 0 | P25: =((D25)+(H25))+(L25) -> 2465.43 | Q25: =(O25)-(P25) -> -2465.43 | R25: =IF(P25=0,"",(O25)/(P25)) -> 0
B26: Total 6100 Payroll Expenses | C26: =((((C21)+(C22))+(C23))+(C24))+(C25) -> 26115.59 | D26: =((((D21)+(D22))+(D23))+(D24))+(D25) -> 25043.44 | E26: =(C26)-(D26) -> 1072.15 | F26: =IF(D26=0,"",(C26)/(D26)) -> 1.0428116 | G26: =((((G21)+(G22))+(G23))+(G24))+(G25) -> 21524.42 | H26: =((((H21)+(H22))+(H23))+(H24))+(H25) -> 25043.44 | I26: =(G26)-(H26) -> -3519.02 | J26: =IF(H26=0,"",(G26)/(H26)) -> 0.85948336 | K26: =((((K21)+(K22))+(K23))+(K24))+(K25) -> 26620.13 | L26: =((((L21)+(L22))+(L23))+(L24))+(L25) -> 25043.44 | M26: =(K26)-(L26) -> 1576.69 | N26: =IF(L26=0,"",(K26)/(L26)) -> 1.0629582 | O26: =((C26)+(G26))+(K26) -> 74260.14 | P26: =((D26)+(H26))+(L26) -> 75130.32 | Q26: =(O26)-(P26) -> -870.18 | R26: =IF(P26=0,"",(O26)/(P26)) -> 0.98841773 | T26: =K26/$K$11 -> 0.092217159 | U26: =L26/$L$11 -> 0.072414767
B27: 6130 Staff Training & Development | C27: =1583.92 -> 1583.92 | D27: =100 -> 100 | E27: =(C27)-(D27) -> 1483.92 | F27: =IF(D27=0,"",(C27)/(D27)) -> 15.8392 | G27: =-1083.92 -> -1083.92 | H27: =100 -> 100 | I27: =(G27)-(H27) -> -1183.92 | J27: =IF(H27=0,"",(G27)/(H27)) -> -10.8392 | K27: =2632.67 -> 2632.67 | L27: =100 -> 100 | M27: =(K27)-(L27) -> 2532.67 | N27: =IF(L27=0,"",(K27)/(L27)) -> 26.3267 | O27: =((C27)+(G27))+(K27) -> 3132.67 | P27: =((D27)+(H27))+(L27) -> 300 | Q27: =(O27)-(P27) -> 2832.67 | R27: =IF(P27=0,"",(O27)/(P27)) -> 10.442233
B28: 6135 Payroll Processing Fees | C28: =919.2 -> 919.2 | D28: =830.14 -> 830.14 | E28: =(C28)-(D28) -> 89.06 | F28: =IF(D28=0,"",(C28)/(D28)) -> 1.1072831 | G28: =883.2 -> 883.2 | H28: =830.14 -> 830.14 | I28: =(G28)-(H28) -> 53.06 | J28: =IF(H28=0,"",(G28)/(H28)) -> 1.0639169 | K28: =956 -> 956 | L28: =830.14 -> 830.14 | M28: =(K28)-(L28) -> 125.86 | N28: =IF(L28=0,"",(K28)/(L28)) -> 1.151613 | O28: =((C28)+(G28))+(K28) -> 2758.4 | P28: =((D28)+(H28))+(L28) -> 2490.42 | Q28: =(O28)-(P28) -> 267.98 | R28: =IF(P28=0,"",(O28)/(P28)) -> 1.1076043
B29: 6150 Employee Reimbursements | C29: =767.58 -> 767.58 | D29: =1647.22 -> 1647.22 | E29: =(C29)-(D29) -> -879.64 | F29: =IF(D29=0,"",(C29)/(D29)) -> 0.46598511 | G29: =63.72 -> 63.72 | H29: =1647.22 -> 1647.22 | I29: =(G29)-(H29) -> -1583.5 | J29: =IF(H29=0,"",(G29)/(H29)) -> 0.038683357 | K29: =0 -> 0 | L29: =1647.22 -> 1647.22 | M29: =(K29)-(L29) -> -1647.22 | N29: =IF(L29=0,"",(K29)/(L29)) -> 0 | O29: =((C29)+(G29))+(K29) -> 831.3 | P29: =((D29)+(H29))+(L29) -> 4941.66 | Q29: =(O29)-(P29) -> -4110.36 | R29: =IF(P29=0,"",(O29)/(P29)) -> 0.16822282
B30: 6155 Employee Gift | C30: =103 -> 103 | D30: =250 -> 250 | E30: =(C30)-(D30) -> -147 | F30: =IF(D30=0,"",(C30)/(D30)) -> 0.412 | G30: =103 -> 103 | H30: =250 -> 250 | I30: =(G30)-(H30) -> -147 | J30: =IF(H30=0,"",(G30)/(H30)) -> 0.412 | L30: =250 -> 250 | M30: =(K30)-(L30) -> -250 | N30: =IF(L30=0,"",(K30)/(L30)) -> 0 | O30: =((C30)+(G30))+(K30) -> 206 | P30: =((D30)+(H30))+(L30) -> 750 | Q30: =(O30)-(P30) -> -544 | R30: =IF(P30=0,"",(O30)/(P30)) -> 0.27466667
B31: 6200 Professional Fees | E31: =(C31)-(D31) -> 0 | F31: =IF(D31=0,"",(C31)/(D31)) | I31: =(G31)-(H31) -> 0 | J31: =IF(H31=0,"",(G31)/(H31)) | M31: =(K31)-(L31) -> 0 | N31: =IF(L31=0,"",(K31)/(L31)) | O31: =((C31)+(G31))+(K31) -> 0 | P31: =((D31)+(H31))+(L31) -> 0 | Q31: =(O31)-(P31) -> 0 | R31: =IF(P31=0,"",(O31)/(P31))
B32: 6205 Legal Fees | C32: =31.59 -> 31.59 | D32: =0 -> 0 | E32: =(C32)-(D32) -> 31.59 | F32: =IF(D32=0,"",(C32)/(D32)) | G32: =10.41 -> 10.41 | H32: =0 -> 0 | I32: =(G32)-(H32) -> 10.41 | J32: =IF(H32=0,"",(G32)/(H32)) | K32: =6296.82 -> 6296.82 | L32: =0 -> 0 | M32: =(K32)-(L32) -> 6296.82 | N32: =IF(L32=0,"",(K32)/(L32)) | O32: =((C32)+(G32))+(K32) -> 6338.82 | P32: =((D32)+(H32))+(L32) -> 0 | Q32: =(O32)-(P32) -> 6338.82 | R32: =IF(P32=0,"",(O32)/(P32))
B33: 6210 IT Fees | C33: =2400 -> 2400 | D33: =2400 -> 2400 | E33: =(C33)-(D33) -> 0 | F33: =IF(D33=0,"",(C33)/(D33)) -> 1 | G33: =2400 -> 2400 | H33: =2400 -> 2400 | I33: =(G33)-(H33) -> 0 | J33: =IF(H33=0,"",(G33)/(H33)) -> 1 | K33: =2400 -> 2400 | L33: =2400 -> 2400 | M33: =(K33)-(L33) -> 0 | N33: =IF(L33=0,"",(K33)/(L33)) -> 1 | O33: =((C33)+(G33))+(K33) -> 7200 | P33: =((D33)+(H33))+(L33) -> 7200 | Q33: =(O33)-(P33) -> 0 | R33: =IF(P33=0,"",(O33)/(P33)) -> 1
B34: 6215 Accounting Fees | C34: =1000 -> 1000 | D34: =1000 -> 1000 | E34: =(C34)-(D34) -> 0 | F34: =IF(D34=0,"",(C34)/(D34)) -> 1 | G34: =1000 -> 1000 | H34: =1000 -> 1000 | I34: =(G34)-(H34) -> 0 | J34: =IF(H34=0,"",(G34)/(H34)) -> 1 | K34: =1093 -> 1093 | L34: =1000 -> 1000 | M34: =(K34)-(L34) -> 93 | N34: =IF(L34=0,"",(K34)/(L34)) -> 1.093 | O34: =((C34)+(G34))+(K34) -> 3093 | P34: =((D34)+(H34))+(L34) -> 3000 | Q34: =(O34)-(P34) -> 93 | R34: =IF(P34=0,"",(O34)/(P34)) -> 1.031
B35: 6220 Professional and Consulting Fees | C35: =1710 -> 1710 | D35: =2500 -> 2500 | E35: =(C35)-(D35) -> -790 | F35: =IF(D35=0,"",(C35)/(D35)) -> 0.684 | G35: =7200 -> 7200 | H35: =2500 -> 2500 | I35: =(G35)-(H35) -> 4700 | J35: =IF(H35=0,"",(G35)/(H35)) -> 2.88 | K35: =3639.99 -> 3639.99 | L35: =2500 -> 2500 | M35: =(K35)-(L35) -> 1139.99 | N35: =IF(L35=0,"",(K35)/(L35)) -> 1.455996 | O35: =((C35)+(G35))+(K35) -> 12549.99 | P35: =((D35)+(H35))+(L35) -> 7500 | Q35: =(O35)-(P35) -> 5049.99 | R35: =IF(P35=0,"",(O35)/(P35)) -> 1.673332 | S35: The fees paid to AR CPA for the 2025 tax return, amounting to $5,500, have been recorded here, which is why the cost is higher in Feb ’26. To smooth this impact in 2026, we have started accruing $500.00 per month.
B36: Total 6200 Professional Fees | C36: =((((C31)+(C32))+(C33))+(C34))+(C35) -> 5141.59 | D36: =((((D31)+(D32))+(D33))+(D34))+(D35) -> 5900 | E36: =(C36)-(D36) -> -758.41 | F36: =IF(D36=0,"",(C36)/(D36)) -> 0.87145593 | G36: =((((G31)+(G32))+(G33))+(G34))+(G35) -> 10610.41 | H36: =((((H31)+(H32))+(H33))+(H34))+(H35) -> 5900 | I36: =(G36)-(H36) -> 4710.41 | J36: =IF(H36=0,"",(G36)/(H36)) -> 1.7983746 | K36: =((((K31)+(K32))+(K33))+(K34))+(K35) -> 13429.81 | L36: =((((L31)+(L32))+(L33))+(L34))+(L35) -> 5900 | M36: =(K36)-(L36) -> 7529.81 | N36: =IF(L36=0,"",(K36)/(L36)) -> 2.276239 | O36: =((C36)+(G36))+(K36) -> 29181.81 | P36: =((D36)+(H36))+(L36) -> 17700 | Q36: =(O36)-(P36) -> 11481.81 | R36: =IF(P36=0,"",(O36)/(P36)) -> 1.6486898 | T36: =K36/$K$11 -> 0.046523399 | U36: =L36/$L$11 -> 0.017060241
B37: 6300 Shareholder's Compensation | E37: =(C37)-(D37) -> 0 | F37: =IF(D37=0,"",(C37)/(D37)) | I37: =(G37)-(H37) -> 0 | J37: =IF(H37=0,"",(G37)/(H37)) | M37: =(K37)-(L37) -> 0 | N37: =IF(L37=0,"",(K37)/(L37)) | O37: =((C37)+(G37))+(K37) -> 0 | P37: =((D37)+(H37))+(L37) -> 0 | Q37: =(O37)-(P37) -> 0 | R37: =IF(P37=0,"",(O37)/(P37))
B38: 6305 Shareholder's Wages & Salaries | C38: =12500 -> 12500 | D38: =10000 -> 10000 | E38: =(C38)-(D38) -> 2500 | F38: =IF(D38=0,"",(C38)/(D38)) -> 1.25 | G38: =10000 -> 10000 | H38: =10000 -> 10000 | I38: =(G38)-(H38) -> 0 | J38: =IF(H38=0,"",(G38)/(H38)) -> 1 | K38: =11071.43 -> 11071.43 | L38: =10000 -> 10000 | M38: =(K38)-(L38) -> 1071.43 | N38: =IF(L38=0,"",(K38)/(L38)) -> 1.107143 | O38: =((C38)+(G38))+(K38) -> 33571.43 | P38: =((D38)+(H38))+(L38) -> 30000 | Q38: =(O38)-(P38) -> 3571.43 | R38: =IF(P38=0,"",(O38)/(P38)) -> 1.1190477
B39: 6310 Shareholder's Health Insurance | C39: =252.75 -> 252.75 | D39: =252 -> 252 | E39: =(C39)-(D39) -> 0.75 | F39: =IF(D39=0,"",(C39)/(D39)) -> 1.0029762 | G39: =252.75 -> 252.75 | H39: =252 -> 252 | I39: =(G39)-(H39) -> 0.75 | J39: =IF(H39=0,"",(G39)/(H39)) -> 1.0029762 | K39: =252.75 -> 252.75 | L39: =252 -> 252 | M39: =(K39)-(L39) -> 0.75 | N39: =IF(L39=0,"",(K39)/(L39)) -> 1.0029762 | O39: =((C39)+(G39))+(K39) -> 758.25 | P39: =((D39)+(H39))+(L39) -> 756 | Q39: =(O39)-(P39) -> 2.25 | R39: =IF(P39=0,"",(O39)/(P39)) -> 1.0029762
B40: 6315 Shareholder's Payroll Taxes | C40: =991.15 -> 991.15 | D40: =800 -> 800 | E40: =(C40)-(D40) -> 191.15 | F40: =IF(D40=0,"",(C40)/(D40)) -> 1.2389375 | G40: =765 -> 765 | H40: =800 -> 800 | I40: =(G40)-(H40) -> -35 | J40: =IF(H40=0,"",(G40)/(H40)) -> 0.95625 | K40: =846.96 -> 846.96 | L40: =800 -> 800 | M40: =(K40)-(L40) -> 46.96 | N40: =IF(L40=0,"",(K40)/(L40)) -> 1.0587 | O40: =((C40)+(G40))+(K40) -> 2603.11 | P40: =((D40)+(H40))+(L40) -> 2400 | Q40: =(O40)-(P40) -> 203.11 | R40: =IF(P40=0,"",(O40)/(P40)) -> 1.0846292
B41: 6320 Shareholder's 401(k) Employer Contributions | C41: =437.5 -> 437.5 | D41: =379.17 -> 379.17 | E41: =(C41)-(D41) -> 58.33 | F41: =IF(D41=0,"",(C41)/(D41)) -> 1.153836 | G41: =350 -> 350 | H41: =379.17 -> 379.17 | I41: =(G41)-(H41) -> -29.17 | J41: =IF(H41=0,"",(G41)/(H41)) -> 0.92306881 | K41: =387.5 -> 387.5 | L41: =379.17 -> 379.17 | M41: =(K41)-(L41) -> 8.33 | N41: =IF(L41=0,"",(K41)/(L41)) -> 1.021969 | O41: =((C41)+(G41))+(K41) -> 1175 | P41: =((D41)+(H41))+(L41) -> 1137.51 | Q41: =(O41)-(P41) -> 37.49 | R41: =IF(P41=0,"",(O41)/(P41)) -> 1.032958
...

Sheet Profit & Loss - Division(Month)
B2: =Cover!A3 -> Pacific Nexus | J2: Home
B3: Profit and Loss by Division | J3: Balance Sheet
B4: =Index!A2 -> Period Ending 03/31/2026 | J4: Profit & Loss
J5: PL-Division (YTD)
C7: Admin & Overhead Cost | G7: NS Printing | K7: PN Agency | O7: PN Photography | S7: PN Printing | W7: YTD
C8: Actual | D8: Budget | E8: Variance | F8: % of Budget | G8: Actual | H8: Budget | I8: Variance | J8: % of Budget | K8: Actual | L8: Budget | M8: Variance | N8: % of Budget | O8: Actual | P8: Budget | Q8: Variance | R8: % of Budget | S8: Actual | T8: Budget | U8: Variance | V8: % of Budget | W8: Actual | X8: Budget | Y8: Variance | Z8: % of Budget
B9: Income
B10: 4005 Sales Revenue | E10: =(C10)-(D10) -> 0 | F10: =IF(D10=0,"",(C10)/(D10)) | G10: =167116.22 -> 167116.22 | H10: =100000 -> 100000 | I10: =(G10)-(H10) -> 67116.22 | J10: =IF(H10=0,"",(G10)/(H10)) -> 1.6711622 | K10: =1550 -> 1550 | L10: =8333.33 -> 8333.33 | M10: =(K10)-(L10) -> -6783.33 | N10: =IF(L10=0,"",(K10)/(L10)) -> 0.18600007 | O10: =45991.14 -> 45991.14 | P10: =104166.67 -> 104166.67 | Q10: =(O10)-(P10) -> -58175.53 | R10: =IF(P10=0,"",(O10)/(P10)) -> 0.44151493 | S10: =74906.02 -> 74906.02 | T10: =133333.33 -> 133333.33 | U10: =(S10)-(T10) -> -58427.31 | V10: =IF(T10=0,"",(S10)/(T10)) -> 0.56179516 | W10: =((((C10)+(G10))+(K10))+(O10))+(S10) -> 289563.38 | X10: =((((D10)+(H10))+(L10))+(P10))+(T10) -> 345833.33 | Y10: =(W10)-(X10) -> -56269.95 | Z10: =IF(X10=0,"",(W10)/(X10)) -> 0.83729171
B11: 4010 Sales Discount | E11: =(C11)-(D11) -> 0 | F11: =IF(D11=0,"",(C11)/(D11)) | I11: =(G11)-(H11) -> 0 | J11: =IF(H11=0,"",(G11)/(H11)) | M11: =(K11)-(L11) -> 0 | N11: =IF(L11=0,"",(K11)/(L11)) | Q11: =(O11)-(P11) -> 0 | R11: =IF(P11=0,"",(O11)/(P11)) | S11: =-895.52 -> -895.52 | U11: =(S11)-(T11) -> -895.52 | V11: =IF(T11=0,"",(S11)/(T11)) | W11: =((((C11)+(G11))+(K11))+(O11))+(S11) -> -895.52 | X11: =((((D11)+(H11))+(L11))+(P11))+(T11) -> 0 | Y11: =(W11)-(X11) -> -895.52 | Z11: =IF(X11=0,"",(W11)/(X11))
B12: Total Income | C12: =(C10)+(C11) -> 0 | D12: =(D10)+(D11) -> 0 | E12: =(C12)-(D12) -> 0 | F12: =IF(D12=0,"",(C12)/(D12)) | G12: =(G10)+(G11) -> 167116.22 | H12: =(H10)+(H11) -> 100000 | I12: =(G12)-(H12) -> 67116.22 | J12: =IF(H12=0,"",(G12)/(H12)) -> 1.6711622 | K12: =(K10)+(K11) -> 1550 | L12: =(L10)+(L11) -> 8333.33 | M12: =(K12)-(L12) -> -6783.33 | N12: =IF(L12=0,"",(K12)/(L12)) -> 0.18600007 | O12: =(O10)+(O11) -> 45991.14 | P12: =(P10)+(P11) -> 104166.67 | Q12: =(O12)-(P12) -> -58175.53 | R12: =IF(P12=0,"",(O12)/(P12)) -> 0.44151493 | S12: =(S10)+(S11) -> 74010.5 | T12: =(T10)+(T11) -> 133333.33 | U12: =(S12)-(T12) -> -59322.83 | V12: =IF(T12=0,"",(S12)/(T12)) -> 0.55507876 | W12: =((((C12)+(G12))+(K12))+(O12))+(S12) -> 288667.86 | X12: =((((D12)+(H12))+(L12))+(P12))+(T12) -> 345833.33 | Y12: =(W12)-(X12) -> -57165.47 | Z12: =IF(X12=0,"",(W12)/(X12)) -> 0.83470225
B13: Cost of Goods Sold
B14: 5005 Cost of Materials | E14: =(C14)-(D14) -> 0 | F14: =IF(D14=0,"",(C14)/(D14)) | G14: =11579.67 -> 11579.67 | H14: =13000 -> 13000 | I14: =(G14)-(H14) -> -1420.33 | J14: =IF(H14=0,"",(G14)/(H14)) -> 0.89074385 | L14: =1083.33 -> 1083.33 | M14: =(K14)-(L14) -> -1083.33 | N14: =IF(L14=0,"",(K14)/(L14)) -> 0 | O14: =4914.15 -> 4914.15 | P14: =13541.67 -> 13541.67 | Q14: =(O14)-(P14) -> -8627.52 | R14: =IF(P14=0,"",(O14)/(P14)) -> 0.36289099 | S14: =18354.09 -> 18354.09 | T14: =17333.33 -> 17333.33 | U14: =(S14)-(T14) -> 1020.76 | V14: =IF(T14=0,"",(S14)/(T14)) -> 1.05889 | W14: =((((C14)+(G14))+(K14))+(O14))+(S14) -> 34847.91 | X14: =((((D14)+(H14))+(L14))+(P14))+(T14) -> 44958.33 | Y14: =(W14)-(X14) -> -10110.42 | Z14: =IF(X14=0,"",(W14)/(X14)) -> 0.77511576
B15: 5015 Travels and Meals | E15: =(C15)-(D15) -> 0 | F15: =IF(D15=0,"",(C15)/(D15)) | I15: =(G15)-(H15) -> 0 | J15: =IF(H15=0,"",(G15)/(H15)) | M15: =(K15)-(L15) -> 0 | N15: =IF(L15=0,"",(K15)/(L15)) | O15: 0 | Q15: =(O15)-(P15) -> 0 | R15: =IF(P15=0,"",(O15)/(P15)) | U15: =(S15)-(T15) -> 0 | V15: =IF(T15=0,"",(S15)/(T15)) | W15: =((((C15)+(G15))+(K15))+(O15))+(S15) -> 0 | X15: =((((D15)+(H15))+(L15))+(P15))+(T15) -> 0 | Y15: =(W15)-(X15) -> 0 | Z15: =IF(X15=0,"",(W15)/(X15))
B16: 5065 Wages | E16: =(C16)-(D16) -> 0 | F16: =IF(D16=0,"",(C16)/(D16)) | G16: =18477.09 -> 18477.09 | H16: =1139.87 -> 1139.87 | I16: =(G16)-(H16) -> 17337.22 | J16: =IF(H16=0,"",(G16)/(H16)) -> 16.209822 | K16: =0 -> 0 | M16: =(K16)-(L16) -> 0 | N16: =IF(L16=0,"",(K16)/(L16)) | O16: =21595.76 -> 21595.76 | P16: =28468.69 -> 28468.69 | Q16: =(O16)-(P16) -> -6872.93 | R16: =IF(P16=0,"",(O16)/(P16)) -> 0.75857934 | S16: =57640.98 -> 57640.98 | T16: =46857.02 -> 46857.02 | U16: =(S16)-(T16) -> 10783.96 | V16: =IF(T16=0,"",(S16)/(T16)) -> 1.2301461 | W16: =((((C16)+(G16))+(K16))+(O16))+(S16) -> 97713.83 | X16: =((((D16)+(H16))+(L16))+(P16))+(T16) -> 76465.58 | Y16: =(W16)-(X16) -> 21248.25 | Z16: =IF(X16=0,"",(W16)/(X16)) -> 1.2778799
B17: 5070 Payroll Tax Expense | E17: =(C17)-(D17) -> 0 | F17: =IF(D17=0,"",(C17)/(D17)) | G17: =1752.46 -> 1752.46 | H17: =91.19 -> 91.19 | I17: =(G17)-(H17) -> 1661.27 | J17: =IF(H17=0,"",(G17)/(H17)) -> 19.217677 | K17: =0 -> 0 | M17: =(K17)-(L17) -> 0 | N17: =IF(L17=0,"",(K17)/(L17)) | O17: =1563.43 -> 1563.43 | P17: =2277.5 -> 2277.5 | Q17: =(O17)-(P17) -> -714.07 | R17: =IF(P17=0,"",(O17)/(P17)) -> 0.68646762 | S17: =4754.34 -> 4754.34 | T17: =3748.56 -> 3748.56 | U17: =(S17)-(T17) -> 1005.78 | V17: =IF(T17=0,"",(S17)/(T17)) -> 1.268311 | W17: =((((C17)+(G17))+(K17))+(O17))+(S17) -> 8070.23 | X17: =((((D17)+(H17))+(L17))+(P17))+(T17) -> 6117.25 | Y17: =(W17)-(X17) -> 1952.98 | Z17: =IF(X17=0,"",(W17)/(X17)) -> 1.3192578
B18: 5075 Employee Benefits | E18: =(C18)-(D18) -> 0 | F18: =IF(D18=0,"",(C18)/(D18)) | G18: =1052.75 -> 1052.75 | I18: =(G18)-(H18) -> 1052.75 | J18: =IF(H18=0,"",(G18)/(H18)) | K18: =0 -> 0 | M18: =(K18)-(L18) -> 0 | N18: =IF(L18=0,"",(K18)/(L18)) | O18: =522.48 -> 522.48 | P18: =1155.98 -> 1155.98 | Q18: =(O18)-(P18) -> -633.5 | R18: =IF(P18=0,"",(O18)/(P18)) -> 0.45198014 | S18: =3253.9 -> 3253.9 | T18: =1902.64 -> 1902.64 | U18: =(S18)-(T18) -> 1351.26 | V18: =IF(T18=0,"",(S18)/(T18)) -> 1.7102027 | W18: =((((C18)+(G18))+(K18))+(O18))+(S18) -> 4829.13 | X18: =((((D18)+(H18))+(L18))+(P18))+(T18) -> 3058.62 | Y18: =(W18)-(X18) -> 1770.51 | Z18: =IF(X18=0,"",(W18)/(X18)) -> 1.5788591
B19: Total Cost of Goods Sold | C19: =((((C14)+(C15))+(C16))+(C17))+(C18) -> 0 | D19: =((((D14)+(D15))+(D16))+(D17))+(D18) -> 0 | E19: =(C19)-(D19) -> 0 | F19: =IF(D19=0,"",(C19)/(D19)) | G19: =((((G14)+(G15))+(G16))+(G17))+(G18) -> 32861.97 | H19: =((((H14)+(H15))+(H16))+(H17))+(H18) -> 14231.06 | I19: =(G19)-(H19) -> 18630.91 | J19: =IF(H19=0,"",(G19)/(H19)) -> 2.3091723 | K19: =((((K14)+(K15))+(K16))+(K17))+(K18) -> 0 | L19: =((((L14)+(L15))+(L16))+(L17))+(L18) -> 1083.33 | M19: =(K19)-(L19) -> -1083.33 | N19: =IF(L19=0,"",(K19)/(L19)) -> 0 | O19: =((((O14)+(O15))+(O16))+(O17))+(O18) -> 28595.82 | P19: =((((P14)+(P15))+(P16))+(P17))+(P18) -> 45443.84 | Q19: =(O19)-(P19) -> -16848.02 | R19: =IF(P19=0,"",(O19)/(P19)) -> 0.62925624 | S19: =((((S14)+(S15))+(S16))+(S17))+(S18) -> 84003.31 | T19: =((((T14)+(T15))+(T16))+(T17))+(T18) -> 69841.55 | U19: =(S19)-(T19) -> 14161.76 | V19: =IF(T19=0,"",(S19)/(T19)) -> 1.2027698 | W19: =((((C19)+(G19))+(K19))+(O19))+(S19) -> 145461.1 | X19: =((((D19)+(H19))+(L19))+(P19))+(T19) -> 130599.78 | Y19: =(W19)-(X19) -> 14861.32 | Z19: =IF(X19=0,"",(W19)/(X19)) -> 1.1137928
B20: Gross Profit | C20: =(C12)-(C19) -> 0 | D20: =(D12)-(D19) -> 0 | E20: =(C20)-(D20) -> 0 | F20: =IF(D20=0,"",(C20)/(D20)) | G20: =(G12)-(G19) -> 134254.25 | H20: =(H12)-(H19) -> 85768.94 | I20: =(G20)-(H20) -> 48485.31 | J20: =IF(H20=0,"",(G20)/(H20)) -> 1.5653015 | K20: =(K12)-(K19) -> 1550 | L20: =(L12)-(L19) -> 7250 | M20: =(K20)-(L20) -> -5700 | N20: =IF(L20=0,"",(K20)/(L20)) -> 0.2137931 | O20: =(O12)-(O19) -> 17395.32 | P20: =(P12)-(P19) -> 58722.83 | Q20: =(O20)-(P20) -> -41327.51 | R20: =IF(P20=0,"",(O20)/(P20)) -> 0.29622755 | S20: =(S12)-(S19) -> -9992.81 | T20: =(T12)-(T19) -> 63491.78 | U20: =(S20)-(T20) -> -73484.59 | V20: =IF(T20=0,"",(S20)/(T20)) -> -0.15738746 | W20: =((((C20)+(G20))+(K20))+(O20))+(S20) -> 143206.76 | X20: =((((D20)+(H20))+(L20))+(P20))+(T20) -> 215233.55 | Y20: =(W20)-(X20) -> -72026.79 | Z20: =IF(X20=0,"",(W20)/(X20)) -> 0.66535519
B21: Expenses
B22: 6100 Payroll Expenses | E22: =(C22)-(D22) -> 0 | F22: =IF(D22=0,"",(C22)/(D22)) | I22: =(G22)-(H22) -> 0 | J22: =IF(H22=0,"",(G22)/(H22)) | M22: =(K22)-(L22) -> 0 | N22: =IF(L22=0,"",(K22)/(L22)) | Q22: =(O22)-(P22) -> 0 | R22: =IF(P22=0,"",(O22)/(P22)) | U22: =(S22)-(T22) -> 0 | V22: =IF(T22=0,"",(S22)/(T22)) | W22: =((((C22)+(G22))+(K22))+(O22))+(S22) -> 0 | X22: =((((D22)+(H22))+(L22))+(P22))+(T22) -> 0 | Y22: =(W22)-(X22) -> 0 | Z22: =IF(X22=0,"",(W22)/(X22))
B23: 6105 Salaries & Wages | C23: =0 -> 0 | D23: =0 -> 0 | E23: =(C23)-(D23) -> 0 | F23: =IF(D23=0,"",(C23)/(D23)) | G23: =14307.67 -> 14307.67 | H23: =13846.18 -> 13846.18 | I23: =(G23)-(H23) -> 461.49 | J23: =IF(H23=0,"",(G23)/(H23)) -> 1.0333298 | K23: =1021.99 -> 1021.99 | L23: =989.01 -> 989.01 | M23: =(K23)-(L23) -> 32.98 | N23: =IF(L23=0,"",(K23)/(L23)) -> 1.0333465 | O23: =6131.87 -> 6131.87 | P23: =5934.08 -> 5934.08 | Q23: =(O23)-(P23) -> 197.79 | R23: =IF(P23=0,"",(O23)/(P23)) -> 1.0333312 | S23: =0 -> 0 | T23: =857.17 -> 857.17 | U23: =(S23)-(T23) -> -857.17 | V23: =IF(T23=0,"",(S23)/(T23)) -> 0 | W23: =((((C23)+(G23))+(K23))+(O23))+(S23) -> 21461.53 | X23: =((((D23)+(H23))+(L23))+(P23))+(T23) -> 21626.44 | Y23: =(W23)-(X23) -> -164.91 | Z23: =IF(X23=0,"",(W23)/(X23)) -> 0.99237461
B24: 6115 Payroll Tax Expense | C24: =104.92 -> 104.92 | D24: =0 -> 0 | E24: =(C24)-(D24) -> 104.92 | F24: =IF(D24=0,"",(C24)/(D24)) | G24: =1306.25 -> 1306.25 | H24: =1107.7 -> 1107.7 | I24: =(G24)-(H24) -> 198.55 | J24: =IF(H24=0,"",(G24)/(H24)) -> 1.1792453 | K24: =285.76 -> 285.76 | L24: =79.12 -> 79.12 | M24: =(K24)-(L24) -> 206.64 | N24: =IF(L24=0,"",(K24)/(L24)) -> 3.611729 | O24: =992.23 -> 992.23 | P24: =474.73 -> 474.73 | Q24: =(O24)-(P24) -> 517.5 | R24: =IF(P24=0,"",(O24)/(P24)) -> 2.0900933 | S24: =1309.53 -> 1309.53 | T24: =68.57 -> 68.57 | U24: =(S24)-(T24) -> 1240.96 | V24: =IF(T24=0,"",(S24)/(T24)) -> 19.09771 | W24: =((((C24)+(G24))+(K24))+(O24))+(S24) -> 3998.69 | X24: =((((D24)+(H24))+(L24))+(P24))+(T24) -> 1730.12 | Y24: =(W24)-(X24) -> 2268.57 | Z24: =IF(X24=0,"",(W24)/(X24)) -> 2.3112212
B25: 6120 Employee Benefits | C25: =0 -> 0 | D25: =0 -> 0 | E25: =(C25)-(D25) -> 0 | F25: =IF(D25=0,"",(C25)/(D25)) | G25: =855.9 -> 855.9 | H25: =553.85 -> 553.85 | I25: =(G25)-(H25) -> 302.05 | J25: =IF(H25=0,"",(G25)/(H25)) -> 1.5453643 | K25: =43.44 -> 43.44 | L25: =39.56 -> 39.56 | M25: =(K25)-(L25) -> 3.88 | N25: =IF(L25=0,"",(K25)/(L25)) -> 1.0980789 | O25: =260.57 -> 260.57 | P25: =237.36 -> 237.36 | Q25: =(O25)-(P25) -> 23.21 | R25: =IF(P25=0,"",(O25)/(P25)) -> 1.097784 | S25: =0 -> 0 | T25: =34.29 -> 34.29 | U25: =(S25)-(T25) -> -34.29 | V25: =IF(T25=0,"",(S25)/(T25)) -> 0 | W25: =((((C25)+(G25))+(K25))+(O25))+(S25) -> 1159.91 | X25: =((((D25)+(H25))+(L25))+(P25))+(T25) -> 865.06 | Y25: =(W25)-(X25) -> 294.85 | Z25: =IF(X25=0,"",(W25)/(X25)) -> 1.3408434
B26: 6125 Employee Bonus | D26: =0 -> 0 | E26: =(C26)-(D26) -> 0 | F26: =IF(D26=0,"",(C26)/(D26)) | H26: =526.16 -> 526.16 | I26: =(G26)-(H26) -> -526.16 | J26: =IF(H26=0,"",(G26)/(H26)) -> 0 | L26: =37.58 -> 37.58 | M26: =(K26)-(L26) -> -37.58 | N26: =IF(L26=0,"",(K26)/(L26)) -> 0 | P26: =225.5 -> 225.5 | Q26: =(O26)-(P26) -> -225.5 | R26: =IF(P26=0,"",(O26)/(P26)) -> 0 | T26: =32.57 -> 32.57 | U26: =(S26)-(T26) -> -32.57 | V26: =IF(T26=0,"",(S26)/(T26)) -> 0 | W26: =((((C26)+(G26))+(K26))+(O26))+(S26) -> 0 | X26: =((((D26)+(H26))+(L26))+(P26))+(T26) -> 821.81 | Y26: =(W26)-(X26) -> -821.81 | Z26: =IF(X26=0,"",(W26)/(X26)) -> 0
B27: Total 6100 Payroll Expenses | C27: =((((C22)+(C23))+(C24))+(C25))+(C26) -> 104.92 | D27: =((((D22)+(D23))+(D24))+(D25))+(D26) -> 0 | E27: =(C27)-(D27) -> 104.92 | F27: =IF(D27=0,"",(C27)/(D27)) | G27: =((((G22)+(G23))+(G24))+(G25))+(G26) -> 16469.82 | H27: =((((H22)+(H23))+(H24))+(H25))+(H26) -> 16033.89 | I27: =(G27)-(H27) -> 435.93 | J27: =IF(H27=0,"",(G27)/(H27)) -> 1.027188 | K27: =((((K22)+(K23))+(K24))+(K25))+(K26) -> 1351.19 | L27: =((((L22)+(L23))+(L24))+(L25))+(L26) -> 1145.27 | M27: =(K27)-(L27) -> 205.92 | N27: =IF(L27=0,"",(K27)/(L27)) -> 1.1798004 | O27: =((((O22)+(O23))+(O24))+(O25))+(O26) -> 7384.67 | P27: =((((P22)+(P23))+(P24))+(P25))+(P26) -> 6871.67 | Q27: =(O27)-(P27) -> 513 | R27: =IF(P27=0,"",(O27)/(P27)) -> 1.0746543 | S27: =((((S22)+(S23))+(S24))+(S25))+(S26) -> 1309.53 | T27: =((((T22)+(T23))+(T24))+(T25))+(T26) -> 992.6 | U27: =(S27)-(T27) -> 316.93 | V27: =IF(T27=0,"",(S27)/(T27)) -> 1.3192928 | W27: =((((C27)+(G27))+(K27))+(O27))+(S27) -> 26620.13 | X27: =((((D27)+(H27))+(L27))+(P27))+(T27) -> 25043.43 | Y27: =(W27)-(X27) -> 1576.7 | Z27: =IF(X27=0,"",(W27)/(X27)) -> 1.0629586
B28: 6130 Staff Training & Development | C28: =2632.67 -> 2632.67 | D28: =100 -> 100 | E28: =(C28)-(D28) -> 2532.67 | F28: =IF(D28=0,"",(C28)/(D28)) -> 26.3267 | I28: =(G28)-(H28) -> 0 | J28: =IF(H28=0,"",(G28)/(H28)) | M28: =(K28)-(L28) -> 0 | N28: =IF(L28=0,"",(K28)/(L28)) | Q28: =(O28)-(P28) -> 0 | R28: =IF(P28=0,"",(O28)/(P28)) | U28: =(S28)-(T28) -> 0 | V28: =IF(T28=0,"",(S28)/(T28)) | W28: =((((C28)+(G28))+(K28))+(O28))+(S28) -> 2632.67 | X28: =((((D28)+(H28))+(L28))+(P28))+(T28) -> 100 | Y28: =(W28)-(X28) -> 2532.67 | Z28: =IF(X28=0,"",(W28)/(X28)) -> 26.3267
B29: 6135 Payroll Processing Fees | C29: =956 -> 956 | D29: =830.14 -> 830.14 | E29: =(C29)-(D29) -> 125.86 | F29: =IF(D29=0,"",(C29)/(D29)) -> 1.151613 | I29: =(G29)-(H29) -> 0 | J29: =IF(H29=0,"",(G29)/(H29)) | M29: =(K29)-(L29) -> 0 | N29: =IF(L29=0,"",(K29)/(L29)) | Q29: =(O29)-(P29) -> 0 | R29: =IF(P29=0,"",(O29)/(P29)) | U29: =(S29)-(T29) -> 0 | V29: =IF(T29=0,"",(S29)/(T29)) | W29: =((((C29)+(G29))+(K29))+(O29))+(S29) -> 956 | X29: =((((D29)+(H29))+(L29))+(P29))+(T29) -> 830.14 | Y29: =(W29)-(X29) -> 125.86 | Z29: =IF(X29=0,"",(W29)/(X29)) -> 1.151613
B30: 6150 Employee Reimbursements | C30: =0 -> 0 | D30: =1647.22 -> 1647.22 | E30: =(C30)-(D30) -> -1647.22 | F30: =IF(D30=0,"",(C30)/(D30)) -> 0 | G30: =0 -> 0 | I30: =(G30)-(H30) -> 0 | J30: =IF(H30=0,"",(G30)/(H30)) | K30: =0 -> 0 | M30: =(K30)-(L30) -> 0 | N30: =IF(L30=0,"",(K30)/(L30)) | O30: =0 -> 0 | Q30: =(O30)-(P30) -> 0 | R30: =IF(P30=0,"",(O30)/(P30)) | S30: =0 -> 0 | U30: =(S30)-(T30) -> 0 | V30: =IF(T30=0,"",(S30)/(T30)) | W30: =((((C30)+(G30))+(K30))+(O30))+(S30) -> 0 | X30: =((((D30)+(H30))+(L30))+(P30))+(T30) -> 1647.22 | Y30: =(W30)-(X30) -> -1647.22 | Z30: =IF(X30=0,"",(W30)/(X30)) -> 0
B31: 6155 Employee Gift | D31: =250 -> 250 | E31: =(C31)-(D31) -> -250 | F31: =IF(D31=0,"",(C31)/(D31)) -> 0 | I31: =(G31)-(H31) -> 0 | J31: =IF(H31=0,"",(G31)/(H31)) | M31: =(K31)-(L31) -> 0 | N31: =IF(L31=0,"",(K31)/(L31)) | Q31: =(O31)-(P31) -> 0 | R31: =IF(P31=0,"",(O31)/(P31)) | U31: =(S31)-(T31) -> 0 | V31: =IF(T31=0,"",(S31)/(T31)) | W31: =((((C31)+(G31))+(K31))+(O31))+(S31) -> 0 | X31: =((((D31)+(H31))+(L31))+(P31))+(T31) -> 250 | Y31: =(W31)-(X31) -> -250 | Z31: =IF(X31=0,"",(W31)/(X31)) -> 0
B32: 6200 Professional Fees | E32: =(C32)-(D32) -> 0 | F32: =IF(D32=0,"",(C32)/(D32)) | I32: =(G32)-(H32) -> 0 | J32: =IF(H32=0,"",(G32)/(H32)) | M32: =(K32)-(L32) -> 0 | N32: =IF(L32=0,"",(K32)/(L32)) | Q32: =(O32)-(P32) -> 0 | R32: =IF(P32=0,"",(O32)/(P32)) | U32: =(S32)-(T32) -> 0 | V32: =IF(T32=0,"",(S32)/(T32)) | W32: =((((C32)+(G32))+(K32))+(O32))+(S32) -> 0 | X32: =((((D32)+(H32))+(L32))+(P32))+(T32) -> 0 | Y32: =(W32)-(X32) -> 0 | Z32: =IF(X32=0,"",(W32)/(X32))
B33: 6205 Legal Fees | C33: =6296.82 -> 6296.82 | E33: =(C33)-(D33) -> 6296.82 | F33: =IF(D33=0,"",(C33)/(D33)) | I33: =(G33)-(H33) -> 0 | J33: =IF(H33=0,"",(G33)/(H33)) | M33: =(K33)-(L33) -> 0 | N33: =IF(L33=0,"",(K33)/(L33)) | Q33: =(O33)-(P33) -> 0 | R33: =IF(P33=0,"",(O33)/(P33)) | U33: =(S33)-(T33) -> 0 | V33: =IF(T33=0,"",(S33)/(T33)) | W33: =((((C33)+(G33))+(K33))+(O33))+(S33) -> 6296.82 | X33: =((((D33)+(H33))+(L33))+(P33))+(T33) -> 0 | Y33: =(W33)-(X33) -> 6296.82 | Z33: =IF(X33=0,"",(W33)/(X33))
B34: 6210 IT Fees | C34: =2400 -> 2400 | D34: =2400 -> 2400 | E34: =(C34)-(D34) -> 0 | F34: =IF(D34=0,"",(C34)/(D34)) -> 1 | I34: =(G34)-(H34) -> 0 | J34: =IF(H34=0,"",(G34)/(H34)) | M34: =(K34)-(L34) -> 0 | N34: =IF(L34=0,"",(K34)/(L34)) | Q34: =(O34)-(P34) -> 0 | R34: =IF(P34=0,"",(O34)/(P34)) | U34: =(S34)-(T34) -> 0 | V34: =IF(T34=0,"",(S34)/(T34)) | W34: =((((C34)+(G34))+(K34))+(O34))+(S34) -> 2400 | X34: =((((D34)+(H34))+(L34))+(P34))+(T34) -> 2400 | Y34: =(W34)-(X34) -> 0 | Z34: =IF(X34=0,"",(W34)/(X34)) -> 1
B35: 6215 Accounting Fees | C35: =1093 -> 1093 | D35: =1000 -> 1000 | E35: =(C35)-(D35) -> 93 | F35: =IF(D35=0,"",(C35)/(D35)) -> 1.093 | I35: =(G35)-(H35) -> 0 | J35: =IF(H35=0,"",(G35)/(H35)) | M35: =(K35)-(L35) -> 0 | N35: =IF(L35=0,"",(K35)/(L35)) | Q35: =(O35)-(P35) -> 0 | R35: =IF(P35=0,"",(O35)/(P35)) | U35: =(S35)-(T35) -> 0 | V35: =IF(T35=0,"",(S35)/(T35)) | W35: =((((C35)+(G35))+(K35))+(O35))+(S35) -> 1093 | X35: =((((D35)+(H35))+(L35))+(P35))+(T35) -> 1000 | Y35: =(W35)-(X35) -> 93 | Z35: =IF(X35=0,"",(W35)/(X35)) -> 1.093
B36: 6220 Professional and Consulting Fees | C36: =2139.99 -> 2139.99 | D36: =2500 -> 2500 | E36: =(C36)-(D36) -> -360.01 | F36: =IF(D36=0,"",(C36)/(D36)) -> 0.855996 | I36: =(G36)-(H36) -> 0 | J36: =IF(H36=0,"",(G36)/(H36)) | M36: =(K36)-(L36) -> 0 | N36: =IF(L36=0,"",(K36)/(L36)) | O36: =1500 -> 1500 | Q36: =(O36)-(P36) -> 1500 | R36: =IF(P36=0,"",(O36)/(P36)) | U36: =(S36)-(T36) -> 0 | V36: =IF(T36=0,"",(S36)/(T36)) | W36: =((((C36)+(G36))+(K36))+(O36))+(S36) -> 3639.99 | X36: =((((D36)+(H36))+(L36))+(P36))+(T36) -> 2500 | Y36: =(W36)-(X36) -> 1139.99 | Z36: =IF(X36=0,"",(W36)/(X36)) -> 1.455996
B37: Total 6200 Professional Fees | C37: =((((C32)+(C33))+(C34))+(C35))+(C36) -> 11929.81 | D37: =((((D32)+(D33))+(D34))+(D35))+(D36) -> 5900 | E37: =(C37)-(D37) -> 6029.81 | F37: =IF(D37=0,"",(C37)/(D37)) -> 2.0220017 | G37: =((((G32)+(G33))+(G34))+(G35))+(G36) -> 0 | H37: =((((H32)+(H33))+(H34))+(H35))+(H36) -> 0 | I37: =(G37)-(H37) -> 0 | J37: =IF(H37=0,"",(G37)/(H37)) | K37: =((((K32)+(K33))+(K34))+(K35))+(K36) -> 0 | L37: =((((L32)+(L33))+(L34))+(L35))+(L36) -> 0 | M37: =(K37)-(L37) -> 0 | N37: =IF(L37=0,"",(K37)/(L37)) | O37: =((((O32)+(O33))+(O34))+(O35))+(O36) -> 1500 | P37: =((((P32)+(P33))+(P34))+(P35))+(P36) -> 0 | Q37: =(O37)-(P37) -> 1500 | R37: =IF(P37=0,"",(O37)/(P37)) | S37: =((((S32)+(S33))+(S34))+(S35))+(S36) -> 0 | T37: =((((T32)+(T33))+(T34))+(T35))+(T36) -> 0 | U37: =(S37)-(T37) -> 0 | V37: =IF(T37=0,"",(S37)/(T37)) | W37: =((((C37)+(G37))+(K37))+(O37))+(S37) -> 13429.81 | X37: =((((D37)+(H37))+(L37))+(P37))+(T37) -> 5900 | Y37: =(W37)-(X37) -> 7529.81 | Z37: =IF(X37=0,"",(W37)/(X37)) -> 2.276239
B38: 6300 Shareholder's Compensation | E38: =(C38)-(D38) -> 0 | F38: =IF(D38=0,"",(C38)/(D38)) | I38: =(G38)-(H38) -> 0 | J38: =IF(H38=0,"",(G38)/(H38)) | M38: =(K38)-(L38) -> 0 | N38: =IF(L38=0,"",(K38)/(L38)) | Q38: =(O38)-(P38) -> 0 | R38: =IF(P38=0,"",(O38)/(P38)) | U38: =(S38)-(T38) -> 0 | V38: =IF(T38=0,"",(S38)/(T38)) | W38: =((((C38)+(G38))+(K38))+(O38))+(S38) -> 0 | X38: =((((D38)+(H38))+(L38))+(P38))+(T38) -> 0 | Y38: =(W38)-(X38) -> 0 | Z38: =IF(X38=0,"",(W38)/(X38))
B39: 6305 Shareholder's Wages & Salaries | C39: =11071.43 -> 11071.43 | D39: =10000 -> 10000 | E39: =(C39)-(D39) -> 1071.43 | F39: =IF(D39=0,"",(C39)/(D39)) -> 1.107143 | I39: =(G39)-(H39) -> 0 | J39: =IF(H39=0,"",(G39)/(H39)) | M39: =(K39)-(L39) -> 0 | N39: =IF(L39=0,"",(K39)/(L39)) | Q39: =(O39)-(P39) -> 0 | R39: =IF(P39=0,"",(O39)/(P39)) | U39: =(S39)-(T39) -> 0 | V39: =IF(T39=0,"",(S39)/(T39)) | W39: =((((C39)+(G39))+(K39))+(O39))+(S39) -> 11071.43 | X39: =((((D39)+(H39))+(L39))+(P39))+(T39) -> 10000 | Y39: =(W39)-(X39) -> 1071.43 | Z39: =IF(X39=0,"",(W39)/(X39)) -> 1.107143
B40: 6310 Shareholder's Health Insurance | C40: =252.75 -> 252.75 | D40: =252 -> 252 | E40: =(C40)-(D40) -> 0.75 | F40: =IF(D40=0,"",(C40)/(D40)) -> 1.0029762 | I40: =(G40)-(H40) -> 0 | J40: =IF(H40=0,"",(G40)/(H40)) | M40: =(K40)-(L40) -> 0 | N40: =IF(L40=0,"",(K40)/(L40)) | Q40: =(O40)-(P40) -> 0 | R40: =IF(P40=0,"",(O40)/(P40)) | U40: =(S40)-(T40) -> 0 | V40: =IF(T40=0,"",(S40)/(T40)) | W40: =((((C40)+(G40))+(K40))+(O40))+(S40) -> 252.75 | X40: =((((D40)+(H40))+(L40))+(P40))+(T40) -> 252 | Y40: =(W40)-(X40) -> 0.75 | Z40: =IF(X40=0,"",(W40)/(X40)) -> 1.0029762
B41: 6315 Shareholder's Payroll Taxes | C41: =846.96 -> 846.96 | D41: =800 -> 800 | E41: =(C41)-(D41) -> 46.96 | F41: =IF(D41=0,"",(C41)/(D41)) -> 1.0587 | I41: =(G41)-(H41) -> 0 | J41: =IF(H41=0,"",(G41)/(H41)) | M41: =(K41)-(L41) -> 0 | N41: =IF(L41=0,"",(K41)/(L41)) | Q41: =(O41)-(P41) -> 0 | R41: =IF(P41=0,"",(O41)/(P41)) | U41: =(S41)-(T41) -> 0 | V41: =IF(T41=0,"",(S41)/(T41)) | W41: =((((C41)+(G41))+(K41))+(O41))+(S41) -> 846.96 | X41: =((((D41)+(H41))+(L41))+(P41))+(T41) -> 800 | Y41: =(W41)-(X41) -> 46.96 | Z41: =IF(X41=0,"",(W41)/(X41)) -> 1.0587
B42: 6320 Shareholder's 401(k) Employer Contributions | C42: =387.5 -> 387.5 | D42: =379.17 -> 379.17 | E42: =(C42)-(D42) -> 8.33 | F42: =IF(D42=0,"",(C42)/(D42)) -> 1.021969 | I42: =(G42)-(H42) -> 0 | J42: =IF(H42=0,"",(G42)/(H42)) | M42: =(K42)-(L42) -> 0 | N42: =IF(L42=0,"",(K42)/(L42)) | Q42: =(O42)-(P42) -> 0 | R42: =IF(P42=0,"",(O42)/(P42)) | U42: =(S42)-(T42) -> 0 | V42: =IF(T42=0,"",(S42)/(T42)) | W42: =((((C42)+(G42))+(K42))+(O42))+(S42) -> 387.5 | X42: =((((D42)+(H42))+(L42))+(P42))+(T42) -> 379.17 | Y42: =(W42)-(X42) -> 8.33 | Z42: =IF(X42=0,"",(W42)/(X42)) -> 1.021969
...

Sheet Profit and Loss - Division(YTD)
B2: =Cover!A3 -> Pacific Nexus | P2: Home
B3: Profit and Loss by Division | P3: Balance Sheet
B4: =Index!A2 -> Period Ending 03/31/2026 | P4: Profit & Loss
P5: PL-Division (Month)
C8: Admin & Overhead Cost - YTD | G8: NS Printing - YTD | K8: PN Agency - YTD | O8: PN Photography - YTD | S8: PN Printing - YTD | W8: YTD
C9: Actual | D9: Budget | E9: Variance | F9: % of Budget | G9: Actual | H9: Budget | I9: Variance | J9: % of Budget | K9: Actual | L9: Budget | M9: Variance | N9: % of Budget | O9: Actual | P9: Budget | Q9: Variance | R9: % of Budget | S9: Actual | T9: Budget | U9: Variance | V9: % of Budget | W9: Actual | X9: Budget | Y9: Variance | Z9: % of Budget
B10: Income
B11: 4005 Sales Revenue | E11: =(C11)-(D11) -> 0 | F11: =IF(D11=0,"",(C11)/(D11)) | G11: =341703.51 -> 341703.51 | H11: =300000 -> 300000 | I11: =(G11)-(H11) -> 41703.51 | J11: =IF(H11=0,"",(G11)/(H11)) -> 1.1390117 | K11: =1189.19 -> 1189.19 | L11: =24999.99 -> 24999.99 | M11: =(K11)-(L11) -> -23810.8 | N11: =IF(L11=0,"",(K11)/(L11)) -> 0.047567619 | O11: =187005.08 -> 187005.08 | P11: =312500.01 -> 312500.01 | Q11: =(O11)-(P11) -> -125494.93 | R11: =IF(P11=0,"",(O11)/(P11)) -> 0.59841624 | S11: =187864.37 -> 187864.37 | T11: =399999.99 -> 399999.99 | U11: =(S11)-(T11) -> -212135.62 | V11: =IF(T11=0,"",(S11)/(T11)) -> 0.46966094 | W11: =((((C11)+(G11))+(K11))+(O11))+(S11) -> 717762.15 | X11: =((((D11)+(H11))+(L11))+(P11))+(T11) -> 1037500 | Y11: =(W11)-(X11) -> -319737.84 | Z11: =IF(X11=0,"",(W11)/(X11)) -> 0.69181895
B12: 4010 Sales Discount | E12: =(C12)-(D12) -> 0 | F12: =IF(D12=0,"",(C12)/(D12)) | I12: =(G12)-(H12) -> 0 | J12: =IF(H12=0,"",(G12)/(H12)) | M12: =(K12)-(L12) -> 0 | N12: =IF(L12=0,"",(K12)/(L12)) | Q12: =(O12)-(P12) -> 0 | R12: =IF(P12=0,"",(O12)/(P12)) | S12: =-3363.73 -> -3363.73 | U12: =(S12)-(T12) -> -3363.73 | V12: =IF(T12=0,"",(S12)/(T12)) | W12: =((((C12)+(G12))+(K12))+(O12))+(S12) -> -3363.73 | X12: =((((D12)+(H12))+(L12))+(P12))+(T12) -> 0 | Y12: =(W12)-(X12) -> -3363.73 | Z12: =IF(X12=0,"",(W12)/(X12))
B13: Total Income | C13: =(C11)+(C12) -> 0 | D13: =(D11)+(D12) -> 0 | E13: =(C13)-(D13) -> 0 | F13: =IF(D13=0,"",(C13)/(D13)) | G13: =(G11)+(G12) -> 341703.51 | H13: =(H11)+(H12) -> 300000 | I13: =(G13)-(H13) -> 41703.51 | J13: =IF(H13=0,"",(G13)/(H13)) -> 1.1390117 | K13: =(K11)+(K12) -> 1189.19 | L13: =(L11)+(L12) -> 24999.99 | M13: =(K13)-(L13) -> -23810.8 | N13: =IF(L13=0,"",(K13)/(L13)) -> 0.047567619 | O13: =(O11)+(O12) -> 187005.08 | P13: =(P11)+(P12) -> 312500.01 | Q13: =(O13)-(P13) -> -125494.93 | R13: =IF(P13=0,"",(O13)/(P13)) -> 0.59841624 | S13: =(S11)+(S12) -> 184500.64 | T13: =(T11)+(T12) -> 399999.99 | U13: =(S13)-(T13) -> -215499.35 | V13: =IF(T13=0,"",(S13)/(T13)) -> 0.46125161 | W13: =((((C13)+(G13))+(K13))+(O13))+(S13) -> 714398.42 | X13: =((((D13)+(H13))+(L13))+(P13))+(T13) -> 1037500 | Y13: =(W13)-(X13) -> -323101.57 | Z13: =IF(X13=0,"",(W13)/(X13)) -> 0.6885768
B14: Cost of Goods Sold
B15: 5005 Cost of Materials | C15: =293.54 -> 293.54 | E15: =(C15)-(D15) -> 293.54 | F15: =IF(D15=0,"",(C15)/(D15)) | G15: =27679.2 -> 27679.2 | H15: =39000 -> 39000 | I15: =(G15)-(H15) -> -11320.8 | J15: =IF(H15=0,"",(G15)/(H15)) -> 0.70972308 | L15: =3249.99 -> 3249.99 | M15: =(K15)-(L15) -> -3249.99 | N15: =IF(L15=0,"",(K15)/(L15)) -> 0 | O15: =9458.81 -> 9458.81 | P15: =40625.01 -> 40625.01 | Q15: =(O15)-(P15) -> -31166.2 | R15: =IF(P15=0,"",(O15)/(P15)) -> 0.23283219 | S15: =49909.42 -> 49909.42 | T15: =51999.99 -> 51999.99 | U15: =(S15)-(T15) -> -2090.57 | V15: =IF(T15=0,"",(S15)/(T15)) -> 0.95979672 | W15: =((((C15)+(G15))+(K15))+(O15))+(S15) -> 87340.97 | X15: =((((D15)+(H15))+(L15))+(P15))+(T15) -> 134874.99 | Y15: =(W15)-(X15) -> -47534.02 | Z15: =IF(X15=0,"",(W15)/(X15)) -> 0.6475698
B16: 5015 Travels and Meals | E16: =(C16)-(D16) -> 0 | F16: =IF(D16=0,"",(C16)/(D16)) | I16: =(G16)-(H16) -> 0 | J16: =IF(H16=0,"",(G16)/(H16)) | M16: =(K16)-(L16) -> 0 | N16: =IF(L16=0,"",(K16)/(L16)) | O16: 0 | Q16: =(O16)-(P16) -> 0 | R16: =IF(P16=0,"",(O16)/(P16)) | U16: =(S16)-(T16) -> 0 | V16: =IF(T16=0,"",(S16)/(T16)) | W16: =((((C16)+(G16))+(K16))+(O16))+(S16) -> 0 | X16: =((((D16)+(H16))+(L16))+(P16))+(T16) -> 0 | Y16: =(W16)-(X16) -> 0 | Z16: =IF(X16=0,"",(W16)/(X16))
B17: 5065 Wages | E17: =(C17)-(D17) -> 0 | F17: =IF(D17=0,"",(C17)/(D17)) | G17: =44070.92 -> 44070.92 | H17: =3419.61 -> 3419.61 | I17: =(G17)-(H17) -> 40651.31 | J17: =IF(H17=0,"",(G17)/(H17)) -> 12.887704 | K17: =0 -> 0 | M17: =(K17)-(L17) -> 0 | N17: =IF(L17=0,"",(K17)/(L17)) | O17: =72626.48 -> 72626.48 | P17: =85406.07 -> 85406.07 | Q17: =(O17)-(P17) -> -12779.59 | R17: =IF(P17=0,"",(O17)/(P17)) -> 0.85036672 | S17: =157318.03 -> 157318.03 | T17: =140571.06 -> 140571.06 | U17: =(S17)-(T17) -> 16746.97 | V17: =IF(T17=0,"",(S17)/(T17)) -> 1.1191353 | W17: =((((C17)+(G17))+(K17))+(O17))+(S17) -> 274015.43 | X17: =((((D17)+(H17))+(L17))+(P17))+(T17) -> 229396.74 | Y17: =(W17)-(X17) -> 44618.69 | Z17: =IF(X17=0,"",(W17)/(X17)) -> 1.1945045
B18: 5070 Payroll Tax Expense | E18: =(C18)-(D18) -> 0 | F18: =IF(D18=0,"",(C18)/(D18)) | G18: =4316.76 -> 4316.76 | H18: =273.57 -> 273.57 | I18: =(G18)-(H18) -> 4043.19 | J18: =IF(H18=0,"",(G18)/(H18)) -> 15.779362 | K18: =0 -> 0 | M18: =(K18)-(L18) -> 0 | N18: =IF(L18=0,"",(K18)/(L18)) | O18: =6218.69 -> 6218.69 | P18: =6832.5 -> 6832.5 | Q18: =(O18)-(P18) -> -613.81 | R18: =IF(P18=0,"",(O18)/(P18)) -> 0.91016319 | S18: =14733.18 -> 14733.18 | T18: =11245.68 -> 11245.68 | U18: =(S18)-(T18) -> 3487.5 | V18: =IF(T18=0,"",(S18)/(T18)) -> 1.3101191 | W18: =((((C18)+(G18))+(K18))+(O18))+(S18) -> 25268.63 | X18: =((((D18)+(H18))+(L18))+(P18))+(T18) -> 18351.75 | Y18: =(W18)-(X18) -> 6916.88 | Z18: =IF(X18=0,"",(W18)/(X18)) -> 1.3769057
B19: 5075 Employee Benefits | E19: =(C19)-(D19) -> 0 | F19: =IF(D19=0,"",(C19)/(D19)) | G19: =1920.46 -> 1920.46 | I19: =(G19)-(H19) -> 1920.46 | J19: =IF(H19=0,"",(G19)/(H19)) | K19: =0 -> 0 | M19: =(K19)-(L19) -> 0 | N19: =IF(L19=0,"",(K19)/(L19)) | O19: =1790.13 -> 1790.13 | P19: =3467.94 -> 3467.94 | Q19: =(O19)-(P19) -> -1677.81 | R19: =IF(P19=0,"",(O19)/(P19)) -> 0.51619405 | S19: =8347.3 -> 8347.3 | T19: =5707.92 -> 5707.92 | U19: =(S19)-(T19) -> 2639.38 | V19: =IF(T19=0,"",(S19)/(T19)) -> 1.4624066 | W19: =((((C19)+(G19))+(K19))+(O19))+(S19) -> 12057.89 | X19: =((((D19)+(H19))+(L19))+(P19))+(T19) -> 9175.86 | Y19: =(W19)-(X19) -> 2882.03 | Z19: =IF(X19=0,"",(W19)/(X19)) -> 1.3140883
B20: Total Cost of Goods Sold | C20: =((((C15)+(C16))+(C17))+(C18))+(C19) -> 293.54 | D20: =((((D15)+(D16))+(D17))+(D18))+(D19) -> 0 | E20: =(C20)-(D20) -> 293.54 | F20: =IF(D20=0,"",(C20)/(D20)) | G20: =((((G15)+(G16))+(G17))+(G18))+(G19) -> 77987.34 | H20: =((((H15)+(H16))+(H17))+(H18))+(H19) -> 42693.18 | I20: =(G20)-(H20) -> 35294.16 | J20: =IF(H20=0,"",(G20)/(H20)) -> 1.8266932 | K20: =((((K15)+(K16))+(K17))+(K18))+(K19) -> 0 | L20: =((((L15)+(L16))+(L17))+(L18))+(L19) -> 3249.99 | M20: =(K20)-(L20) -> -3249.99 | N20: =IF(L20=0,"",(K20)/(L20)) -> 0 | O20: =((((O15)+(O16))+(O17))+(O18))+(O19) -> 90094.11 | P20: =((((P15)+(P16))+(P17))+(P18))+(P19) -> 136331.52 | Q20: =(O20)-(P20) -> -46237.41 | R20: =IF(P20=0,"",(O20)/(P20)) -> 0.66084578 | S20: =((((S15)+(S16))+(S17))+(S18))+(S19) -> 230307.93 | T20: =((((T15)+(T16))+(T17))+(T18))+(T19) -> 209524.65 | U20: =(S20)-(T20) -> 20783.28 | V20: =IF(T20=0,"",(S20)/(T20)) -> 1.0991925 | W20: =((((C20)+(G20))+(K20))+(O20))+(S20) -> 398682.92 | X20: =((((D20)+(H20))+(L20))+(P20))+(T20) -> 391799.34 | Y20: =(W20)-(X20) -> 6883.58 | Z20: =IF(X20=0,"",(W20)/(X20)) -> 1.0175691
B21: Gross Profit | C21: =(C13)-(C20) -> -293.54 | D21: =(D13)-(D20) -> 0 | E21: =(C21)-(D21) -> -293.54 | F21: =IF(D21=0,"",(C21)/(D21)) | G21: =(G13)-(G20) -> 263716.17 | H21: =(H13)-(H20) -> 257306.82 | I21: =(G21)-(H21) -> 6409.35 | J21: =IF(H21=0,"",(G21)/(H21)) -> 1.0249094 | K21: =(K13)-(K20) -> 1189.19 | L21: =(L13)-(L20) -> 21750 | M21: =(K21)-(L21) -> -20560.81 | N21: =IF(L21=0,"",(K21)/(L21)) -> 0.054675402 | O21: =(O13)-(O20) -> 96910.97 | P21: =(P13)-(P20) -> 176168.49 | Q21: =(O21)-(P21) -> -79257.52 | R21: =IF(P21=0,"",(O21)/(P21)) -> 0.55010388 | S21: =(S13)-(S20) -> -45807.29 | T21: =(T13)-(T20) -> 190475.34 | U21: =(S21)-(T21) -> -236282.63 | V21: =IF(T21=0,"",(S21)/(T21)) -> -0.24048935 | W21: =((((C21)+(G21))+(K21))+(O21))+(S21) -> 315715.5 | X21: =((((D21)+(H21))+(L21))+(P21))+(T21) -> 645700.65 | Y21: =(W21)-(X21) -> -329985.15 | Z21: =IF(X21=0,"",(W21)/(X21)) -> 0.48895026
B22: Expenses
